<?xml version="1.0" encoding="UTF-8"?>
<testng-results ignored="0" total="2" passed="0" failed="2" skipped="0">
  <reporter-output>
  </reporter-output>
  <suite started-at="2024-11-08T13:14:02 IST" name="Failed suite [Failed suite [Suite]]" finished-at="2024-11-08T13:14:02 IST" duration-ms="148">
    <groups>
    </groups>
    <test started-at="2024-11-08T13:14:02 IST" name="TestRunner2(failed)(failed)" finished-at="2024-11-08T13:14:02 IST" duration-ms="148">
      <class name="distributedparallel.Test1">
        <test-method signature="demo1()[pri:0, instance:distributedparallel.Test1@fbd1f6]" started-at="2024-11-08T13:14:02 IST" name="demo1" finished-at="2024-11-08T13:14:02 IST" duration-ms="28" status="FAIL">
          <exception class="java.lang.AssertionError">
            <message>
              <![CDATA[null]]>
            </message>
            <full-stacktrace>
              <![CDATA[java.lang.AssertionError: null
at org.testng.Assert.fail(Assert.java:111)
at org.testng.Assert.fail(Assert.java:116)
at distributedparallel.Test1.demo1(Test1.java:10)
at java.base/jdk.internal.reflect.DirectMethodHandleAccessor.invoke(DirectMethodHandleAccessor.java:103)
at java.base/java.lang.reflect.Method.invoke(Method.java:580)
at org.testng.internal.invokers.MethodInvocationHelper.invokeMethod(MethodInvocationHelper.java:141)
at org.testng.internal.invokers.TestInvoker.invokeMethod(TestInvoker.java:686)
at org.testng.internal.invokers.TestInvoker.invokeTestMethod(TestInvoker.java:230)
at org.testng.internal.invokers.MethodRunner.runInSequence(MethodRunner.java:63)
at org.testng.internal.invokers.TestInvoker$MethodInvocationAgent.invoke(TestInvoker.java:992)
at org.testng.internal.invokers.TestInvoker.invokeTestMethods(TestInvoker.java:203)
at org.testng.internal.invokers.TestMethodWorker.invokeTestMethods(TestMethodWorker.java:154)
at org.testng.internal.invokers.TestMethodWorker.run(TestMethodWorker.java:134)
at java.base/java.util.ArrayList.forEach(ArrayList.java:1597)
at org.testng.TestRunner.privateRun(TestRunner.java:739)
at org.testng.TestRunner.run(TestRunner.java:614)
at org.testng.SuiteRunner.runTest(SuiteRunner.java:421)
at org.testng.SuiteRunner$SuiteWorker.run(SuiteRunner.java:463)
at org.testng.internal.thread.ThreadUtil.lambda$execute$0(ThreadUtil.java:64)
at java.base/java.util.concurrent.FutureTask.run(FutureTask.java:317)
at java.base/java.util.concurrent.ThreadPoolExecutor.runWorker(ThreadPoolExecutor.java:1144)
at java.base/java.util.concurrent.ThreadPoolExecutor$Worker.run(ThreadPoolExecutor.java:642)
at java.base/java.lang.Thread.run(Thread.java:1570)
]]>
            </full-stacktrace>
          </exception> <!-- java.lang.AssertionError -->
          <reporter-output>
          </reporter-output>
        </test-method> <!-- demo1 -->
      </class> <!-- distributedparallel.Test1 -->
    </test> <!-- TestRunner2(failed)(failed) -->
    <test started-at="2024-11-08T13:14:02 IST" name="TestRunner1(failed)(failed)" finished-at="2024-11-08T13:14:02 IST" duration-ms="148">
      <class name="distributedparallel.Test5">
        <test-method signature="demo1()[pri:0, instance:distributedparallel.Test5@34123d65]" started-at="2024-11-08T13:14:02 IST" name="demo1" finished-at="2024-11-08T13:14:02 IST" duration-ms="28" status="FAIL">
          <exception class="java.lang.AssertionError">
            <message>
              <![CDATA[null]]>
            </message>
            <full-stacktrace>
              <![CDATA[java.lang.AssertionError: null
at org.testng.Assert.fail(Assert.java:111)
at org.testng.Assert.fail(Assert.java:116)
at distributedparallel.Test5.demo1(Test5.java:10)
at java.base/jdk.internal.reflect.DirectMethodHandleAccessor.invoke(DirectMethodHandleAccessor.java:103)
at java.base/java.lang.reflect.Method.invoke(Method.java:580)
at org.testng.internal.invokers.MethodInvocationHelper.invokeMethod(MethodInvocationHelper.java:141)
at org.testng.internal.invokers.TestInvoker.invokeMethod(TestInvoker.java:686)
at org.testng.internal.invokers.TestInvoker.invokeTestMethod(TestInvoker.java:230)
at org.testng.internal.invokers.MethodRunner.runInSequence(MethodRunner.java:63)
at org.testng.internal.invokers.TestInvoker$MethodInvocationAgent.invoke(TestInvoker.java:992)
at org.testng.internal.invokers.TestInvoker.invokeTestMethods(TestInvoker.java:203)
at org.testng.internal.invokers.TestMethodWorker.invokeTestMethods(TestMethodWorker.java:154)
at org.testng.internal.invokers.TestMethodWorker.run(TestMethodWorker.java:134)
at java.base/java.util.ArrayList.forEach(ArrayList.java:1597)
at org.testng.TestRunner.privateRun(TestRunner.java:739)
at org.testng.TestRunner.run(TestRunner.java:614)
at org.testng.SuiteRunner.runTest(SuiteRunner.java:421)
at org.testng.SuiteRunner$SuiteWorker.run(SuiteRunner.java:463)
at org.testng.internal.thread.ThreadUtil.lambda$execute$0(ThreadUtil.java:64)
at java.base/java.util.concurrent.FutureTask.run(FutureTask.java:317)
at java.base/java.util.concurrent.ThreadPoolExecutor.runWorker(ThreadPoolExecutor.java:1144)
at java.base/java.util.concurrent.ThreadPoolExecutor$Worker.run(ThreadPoolExecutor.java:642)
at java.base/java.lang.Thread.run(Thread.java:1570)
]]>
            </full-stacktrace>
          </exception> <!-- java.lang.AssertionError -->
          <reporter-output>
          </reporter-output>
        </test-method> <!-- demo1 -->
      </class> <!-- distributedparallel.Test5 -->
    </test> <!-- TestRunner1(failed)(failed) -->
  </suite> <!-- Failed suite [Failed suite [Suite]] -->
</testng-results>
